nohup: ignoring input
INFO:     Started server process [1439]
INFO:     Waiting for application startup.
INFO:     Application startup complete.
INFO:     Uvicorn running on http://0.0.0.0:8004 (Press CTRL+C to quit)
INFO:     127.0.0.1:34088 - "POST /create_order?order_id=123&product_name=example_product HTTP/1.1" 500 Internal Server Error
ERROR:    Exception in ASGI application
Traceback (most recent call last):
  File "/usr/lib/python3/dist-packages/urllib3/connection.py", line 159, in _new_conn
    conn = connection.create_connection(
  File "/usr/lib/python3/dist-packages/urllib3/util/connection.py", line 61, in create_connection
    for res in socket.getaddrinfo(host, port, family, socket.SOCK_STREAM):
  File "/usr/lib/python3.8/socket.py", line 918, in getaddrinfo
    for res in _socket.getaddrinfo(host, port, family, type, proto, flags):
socket.gaierror: [Errno -2] Name or service not known

During handling of the above exception, another exception occurred:

Traceback (most recent call last):
  File "/usr/lib/python3/dist-packages/urllib3/connectionpool.py", line 665, in urlopen
    httplib_response = self._make_request(
  File "/usr/lib/python3/dist-packages/urllib3/connectionpool.py", line 387, in _make_request
    conn.request(method, url, **httplib_request_kw)
  File "/usr/lib/python3.8/http/client.py", line 1256, in request
    self._send_request(method, url, body, headers, encode_chunked)
  File "/usr/lib/python3.8/http/client.py", line 1302, in _send_request
    self.endheaders(body, encode_chunked=encode_chunked)
  File "/usr/lib/python3.8/http/client.py", line 1251, in endheaders
    self._send_output(message_body, encode_chunked=encode_chunked)
  File "/usr/lib/python3.8/http/client.py", line 1011, in _send_output
    self.send(msg)
  File "/usr/lib/python3.8/http/client.py", line 951, in send
    self.connect()
  File "/usr/lib/python3/dist-packages/urllib3/connection.py", line 187, in connect
    conn = self._new_conn()
  File "/usr/lib/python3/dist-packages/urllib3/connection.py", line 171, in _new_conn
    raise NewConnectionError(
urllib3.exceptions.NewConnectionError: <urllib3.connection.HTTPConnection object at 0x7f0b41b01610>: Failed to establish a new connection: [Errno -2] Name or service not known

During handling of the above exception, another exception occurred:

Traceback (most recent call last):
  File "/usr/lib/python3/dist-packages/requests/adapters.py", line 439, in send
    resp = conn.urlopen(
  File "/usr/lib/python3/dist-packages/urllib3/connectionpool.py", line 719, in urlopen
    retries = retries.increment(
  File "/usr/lib/python3/dist-packages/urllib3/util/retry.py", line 436, in increment
    raise MaxRetryError(_pool, url, error or ResponseError(cause))
urllib3.exceptions.MaxRetryError: HTTPConnectionPool(host='payments_service', port=8002): Max retries exceeded with url: /pay (Caused by NewConnectionError('<urllib3.connection.HTTPConnection object at 0x7f0b41b01610>: Failed to establish a new connection: [Errno -2] Name or service not known'))

During handling of the above exception, another exception occurred:

Traceback (most recent call last):
  File "/usr/local/lib/python3.8/dist-packages/uvicorn/protocols/http/httptools_impl.py", line 399, in run_asgi
    result = await app(  # type: ignore[func-returns-value]
  File "/usr/local/lib/python3.8/dist-packages/uvicorn/middleware/proxy_headers.py", line 70, in __call__
    return await self.app(scope, receive, send)
  File "/usr/local/lib/python3.8/dist-packages/fastapi/applications.py", line 1054, in __call__
    await super().__call__(scope, receive, send)
  File "/usr/local/lib/python3.8/dist-packages/starlette/applications.py", line 123, in __call__
    await self.middleware_stack(scope, receive, send)
  File "/usr/local/lib/python3.8/dist-packages/starlette/middleware/errors.py", line 186, in __call__
    raise exc
  File "/usr/local/lib/python3.8/dist-packages/starlette/middleware/errors.py", line 164, in __call__
    await self.app(scope, receive, _send)
  File "/usr/local/lib/python3.8/dist-packages/starlette/middleware/exceptions.py", line 65, in __call__
    await wrap_app_handling_exceptions(self.app, conn)(scope, receive, send)
  File "/usr/local/lib/python3.8/dist-packages/starlette/_exception_handler.py", line 64, in wrapped_app
    raise exc
  File "/usr/local/lib/python3.8/dist-packages/starlette/_exception_handler.py", line 53, in wrapped_app
    await app(scope, receive, sender)
  File "/usr/local/lib/python3.8/dist-packages/starlette/routing.py", line 756, in __call__
    await self.middleware_stack(scope, receive, send)
  File "/usr/local/lib/python3.8/dist-packages/starlette/routing.py", line 776, in app
    await route.handle(scope, receive, send)
  File "/usr/local/lib/python3.8/dist-packages/starlette/routing.py", line 297, in handle
    await self.app(scope, receive, send)
  File "/usr/local/lib/python3.8/dist-packages/starlette/routing.py", line 77, in app
    await wrap_app_handling_exceptions(app, request)(scope, receive, send)
  File "/usr/local/lib/python3.8/dist-packages/starlette/_exception_handler.py", line 64, in wrapped_app
    raise exc
  File "/usr/local/lib/python3.8/dist-packages/starlette/_exception_handler.py", line 53, in wrapped_app
    await app(scope, receive, sender)
  File "/usr/local/lib/python3.8/dist-packages/starlette/routing.py", line 72, in app
    response = await func(request)
  File "/usr/local/lib/python3.8/dist-packages/fastapi/routing.py", line 278, in app
    raw_response = await run_endpoint_function(
  File "/usr/local/lib/python3.8/dist-packages/fastapi/routing.py", line 193, in run_endpoint_function
    return await run_in_threadpool(dependant.call, **values)
  File "/usr/local/lib/python3.8/dist-packages/starlette/concurrency.py", line 42, in run_in_threadpool
    return await anyio.to_thread.run_sync(func, *args)
  File "/usr/local/lib/python3.8/dist-packages/anyio/to_thread.py", line 56, in run_sync
    return await get_async_backend().run_sync_in_worker_thread(
  File "/usr/local/lib/python3.8/dist-packages/anyio/_backends/_asyncio.py", line 2177, in run_sync_in_worker_thread
    return await future
  File "/usr/local/lib/python3.8/dist-packages/anyio/_backends/_asyncio.py", line 859, in run
    result = context.run(func, *args)
  File "/mnt/c/Users/pc/Documents/AZURE_PROJECTS_UYI/micro_services_k8s/micro_services_with_k8s_CI-CD_pipeline/microservices_project/orders_service/main.py", line 11, in create_order
    payment_response = requests.post("http://payments_service:8002/pay", json={"order_id": order_id, "amount": 100.0})
  File "/usr/lib/python3/dist-packages/requests/api.py", line 116, in post
    return request('post', url, data=data, json=json, **kwargs)
  File "/usr/lib/python3/dist-packages/requests/api.py", line 60, in request
    return session.request(method=method, url=url, **kwargs)
  File "/usr/lib/python3/dist-packages/requests/sessions.py", line 533, in request
    resp = self.send(prep, **send_kwargs)
  File "/usr/lib/python3/dist-packages/requests/sessions.py", line 646, in send
    r = adapter.send(request, **kwargs)
  File "/usr/lib/python3/dist-packages/requests/adapters.py", line 516, in send
    raise ConnectionError(e, request=request)
requests.exceptions.ConnectionError: HTTPConnectionPool(host='payments_service', port=8002): Max retries exceeded with url: /pay (Caused by NewConnectionError('<urllib3.connection.HTTPConnection object at 0x7f0b41b01610>: Failed to establish a new connection: [Errno -2] Name or service not known'))
